src/screens/Orderbook/__mocks__/reducePendingGroupUpdatesToState.updates1.json
[
    {
        "kind": "u",
        "updates": {
            "feed": "book_ui_1",
            "product_id": "PI_XBTUSD",
            "bids": [
                [37293.5, 22819],
                [37549.5, 0],
                [37573, 240000],
                [37626.5, 48750],
                [37628.5, 0],
                [37631.5, 0],
                [37636.5, 2500],
                [37653, 0],
                [37675, 0],
                [37677.5, 0],
                [37678, 0],
                [37680, 150000],
                [37680.5, 0],
                [37681, 0],
                [37681.5, 151984],
                [37682, 0],
                [37684, 0],
                [37686, 1982],
                [37687.5, 23750],
                [37688, 14170],
                [37688.5, 0],
                [37689.5, 3070],
                [37690, 151841],
                [37695, 2305],
                [37697, 0],
                [37700.5, 10000],
                [37701, 518],
                [37701.5, 5591]
            ],
            "asks": [
                [37713, 0],
                [37719, 0],
                [37719.5, 0],
                [37720, 0],
                [37720.5, 0],
                [37725.5, 367],
                [37726, 0],
                [37745.5, 5000],
                [37746, 1113],
                [37751.5, 68474],
                [37756, 20100],
                [37760, 0],
                [37761, 0],
                [37763, 0],
                [37764, 136181],
                [37765, 0],
                [37767.5, 96662],
                [37769, 0],
                [37772, 150000],
                [37773.5, 0],
                [37777.5, 150000],
                [37787, 0],
                [37803.5, 8952],
                [37807.5, 0],
                [37816, 0],
                [37816.5, 0],
                [37822, 200],
                [37822.5, 0],
                [37824.5, 720001],
                [37825, 48750],
                [38120.5, 32460],
                [38191.5, 5827],
                [38462, 0],
                [38465, 0],
                [38465.5, 15000],
                [38468.5, 15830]
            ]
        },
        "selectedLastState": { "bids": { "3768050": 14170 }, "asks": {} }
    },
    {
        "kind": "u",
        "updates": {
            "feed": "book_ui_1",
            "product_id": "PI_XBTUSD",
            "bids": [],
            "asks": [
                [38465.5, 0],
                [38468.5, 30830]
            ]
        },
        "selectedLastState": { "bids": {}, "asks": {} }
    },
    {
        "kind": "u",
        "updates": {
            "feed": "book_ui_1",
            "product_id": "PI_XBTUSD",
            "bids": [],
            "asks": [[38120.5, 0]]
        },
        "selectedLastState": { "bids": {}, "asks": {} }
    },
    {
        "kind": "u",
        "updates": {
            "feed": "book_ui_1",
            "product_id": "PI_XBTUSD",
            "bids": [[37701.5, 12085]],
            "asks": []
        },
        "selectedLastState": { "bids": {}, "asks": {} }
    },
    {
        "kind": "u",
        "updates": {
            "feed": "book_ui_1",
            "product_id": "PI_XBTUSD",
            "bids": [],
            "asks": [[38191.5, 10891]]
        },
        "selectedLastState": { "bids": {}, "asks": {} }
    }
]
